[2024-09-06T07:23:53.357+0000] {local_task_job_runner.py:120} INFO - ::group::Pre task execution logs
[2024-09-06T07:23:53.383+0000] {taskinstance.py:2076} INFO - Dependencies all met for dep_context=non-requeueable deps ti=<TaskInstance: etl_data_pipeline.load_data_to_postgres manual__2024-09-06T07:21:35.545405+00:00 [queued]>
[2024-09-06T07:23:53.390+0000] {taskinstance.py:2076} INFO - Dependencies all met for dep_context=requeueable deps ti=<TaskInstance: etl_data_pipeline.load_data_to_postgres manual__2024-09-06T07:21:35.545405+00:00 [queued]>
[2024-09-06T07:23:53.390+0000] {taskinstance.py:2306} INFO - Starting attempt 1 of 2
[2024-09-06T07:23:53.404+0000] {taskinstance.py:2330} INFO - Executing <Task(PythonOperator): load_data_to_postgres> on 2024-09-06 07:21:35.545405+00:00
[2024-09-06T07:23:53.410+0000] {warnings.py:112} WARNING - /home/***/.local/lib/python3.12/site-packages/***/task/task_runner/standard_task_runner.py:61: DeprecationWarning: This process (pid=233) is multi-threaded, use of fork() may lead to deadlocks in the child.
  pid = os.fork()

[2024-09-06T07:23:53.411+0000] {standard_task_runner.py:63} INFO - Started process 234 to run task
[2024-09-06T07:23:53.411+0000] {standard_task_runner.py:90} INFO - Running: ['***', 'tasks', 'run', 'etl_data_pipeline', 'load_data_to_postgres', 'manual__2024-09-06T07:21:35.545405+00:00', '--job-id', '11', '--raw', '--subdir', 'DAGS_FOLDER/newspipeline.py', '--cfg-path', '/tmp/tmp8ash4xc3']
[2024-09-06T07:23:53.412+0000] {standard_task_runner.py:91} INFO - Job 11: Subtask load_data_to_postgres
[2024-09-06T07:23:53.454+0000] {task_command.py:426} INFO - Running <TaskInstance: etl_data_pipeline.load_data_to_postgres manual__2024-09-06T07:21:35.545405+00:00 [running]> on host ca47fb49acc7
[2024-09-06T07:23:54.876+0000] {taskinstance.py:2648} INFO - Exporting env vars: AIRFLOW_CTX_DAG_OWNER='***' AIRFLOW_CTX_DAG_ID='etl_data_pipeline' AIRFLOW_CTX_TASK_ID='load_data_to_postgres' AIRFLOW_CTX_EXECUTION_DATE='2024-09-06T07:21:35.545405+00:00' AIRFLOW_CTX_TRY_NUMBER='1' AIRFLOW_CTX_DAG_RUN_ID='manual__2024-09-06T07:21:35.545405+00:00'
[2024-09-06T07:23:54.877+0000] {taskinstance.py:430} INFO - ::endgroup::
[2024-09-06T07:23:55.145+0000] {taskinstance.py:441} INFO - ::group::Post task execution logs
[2024-09-06T07:23:55.145+0000] {taskinstance.py:2905} ERROR - Task failed with exception
Traceback (most recent call last):
  File "/home/airflow/.local/lib/python3.12/site-packages/airflow/models/taskinstance.py", line 465, in _execute_task
    result = _execute_callable(context=context, **execute_callable_kwargs)
             ^^^^^^^^^^^^^^^^^^^^^^^^^^^^^^^^^^^^^^^^^^^^^^^^^^^^^^^^^^^^^
  File "/home/airflow/.local/lib/python3.12/site-packages/airflow/models/taskinstance.py", line 432, in _execute_callable
    return execute_callable(context=context, **execute_callable_kwargs)
           ^^^^^^^^^^^^^^^^^^^^^^^^^^^^^^^^^^^^^^^^^^^^^^^^^^^^^^^^^^^^
  File "/home/airflow/.local/lib/python3.12/site-packages/airflow/models/baseoperator.py", line 401, in wrapper
    return func(self, *args, **kwargs)
           ^^^^^^^^^^^^^^^^^^^^^^^^^^^
  File "/home/airflow/.local/lib/python3.12/site-packages/airflow/operators/python.py", line 235, in execute
    return_value = self.execute_callable()
                   ^^^^^^^^^^^^^^^^^^^^^^^
  File "/home/airflow/.local/lib/python3.12/site-packages/airflow/operators/python.py", line 252, in execute_callable
    return self.python_callable(*self.op_args, **self.op_kwargs)
           ^^^^^^^^^^^^^^^^^^^^^^^^^^^^^^^^^^^^^^^^^^^^^^^^^^^^^
  File "/opt/airflow/dags/newspipeline.py", line 94, in load_data_to_postgres
    json.dumps(row['authors']), row['image']
    ^^^^^^^^^^^^^^^^^^^^^^^^^^
  File "/usr/local/lib/python3.12/json/__init__.py", line 231, in dumps
    return _default_encoder.encode(obj)
           ^^^^^^^^^^^^^^^^^^^^^^^^^^^^
  File "/usr/local/lib/python3.12/json/encoder.py", line 200, in encode
    chunks = self.iterencode(o, _one_shot=True)
             ^^^^^^^^^^^^^^^^^^^^^^^^^^^^^^^^^^
  File "/usr/local/lib/python3.12/json/encoder.py", line 258, in iterencode
    return _iterencode(o, 0)
           ^^^^^^^^^^^^^^^^^
  File "/usr/local/lib/python3.12/json/encoder.py", line 180, in default
    raise TypeError(f'Object of type {o.__class__.__name__} '
TypeError: Object of type ndarray is not JSON serializable
[2024-09-06T07:23:55.157+0000] {taskinstance.py:1206} INFO - Marking task as UP_FOR_RETRY. dag_id=etl_data_pipeline, task_id=load_data_to_postgres, run_id=manual__2024-09-06T07:21:35.545405+00:00, execution_date=20240906T072135, start_date=20240906T072353, end_date=20240906T072355
[2024-09-06T07:23:55.171+0000] {standard_task_runner.py:110} ERROR - Failed to execute job 11 for task load_data_to_postgres (Object of type ndarray is not JSON serializable; 234)
[2024-09-06T07:23:55.212+0000] {local_task_job_runner.py:240} INFO - Task exited with return code 1
[2024-09-06T07:23:55.229+0000] {taskinstance.py:3503} INFO - 0 downstream tasks scheduled from follow-on schedule check
[2024-09-06T07:23:55.231+0000] {local_task_job_runner.py:222} INFO - ::endgroup::
